<?xml version="1.0" encoding="utf-8"?>
<!-- This URDF was automatically created by SolidWorks to URDF Exporter! Originally created by Stephen Brawner (brawner@gmail.com) 
     Commit Version: 1.6.0-4-g7f85cfe  Build Version: 1.6.7995.38578
     For more information, please see http://wiki.ros.org/sw_urdf_exporter -->
<robot
  name="robotic_arm_urdf">
  <link
    name="base_link">
    <inertial>
      <origin
        xyz="-4.42354486374086E-17 3.46944695195361E-17 0.0738760171205099"
        rpy="0 0 0" />
      <mass
        value="17.1466031047214" />
      <inertia
        ixx="0.192001545021743"
        ixy="4.94231299318652E-10"
        ixz="-5.20420392413465E-17"
        iyy="0.192001560775053"
        iyz="5.28557777898092E-17"
        izz="0.295440370143331" />
    </inertial>
    <visual>
      <origin
        xyz="0 0 0"
        rpy="0 0 0" />
      <geometry>
        <mesh
          filename="package://robotic_arm_urdf/meshes/base_link.STL" />
      </geometry>
      <material
        name="">
        <color
          rgba="0.792156862745098 0.819607843137255 0.933333333333333 1" />
      </material>
    </visual>
    <collision>
      <origin
        xyz="0 0 0"
        rpy="0 0 0" />
      <geometry>
        <mesh
          filename="package://robotic_arm_urdf/meshes/base_link.STL" />
      </geometry>
    </collision>
  </link>
  <link
    name="link_1">
    <inertial>
      <origin
        xyz="-7.8988E-11 -2.573E-14 0.11047"
        rpy="0 0 0" />
      <mass
        value="3.0905" />
      <inertia
        ixx="0.025388"
        ixy="-1.4177E-12"
        ixz="-7.4535E-12"
        iyy="0.026302"
        iyz="-2.5317E-15"
        izz="0.019632" />
    </inertial>
    <visual>
      <origin
        xyz="0 0 0"
        rpy="0 0 0" />
      <geometry>
        <mesh
          filename="package://robotic_arm_urdf/meshes/link_1.STL" />
      </geometry>
      <material
        name="">
        <color
          rgba="1 1 1 1" />
      </material>
    </visual>
    <collision>
      <origin
        xyz="0 0 0"
        rpy="0 0 0" />
      <geometry>
        <mesh
          filename="package://robotic_arm_urdf/meshes/link_1.STL" />
      </geometry>
    </collision>
  </link>
  <joint
    name="joint_1"
    type="revolute">
    <origin
      xyz="0 0 0.2"
      rpy="0 0 -1.5708" />
    <parent
      link="base_link" />
    <child
      link="link_1" />
    <axis
      xyz="0 0 1" />
    <limit
      lower="-3.142"
      upper="3.142"
      effort="300"
      velocity="3" />
  </joint>
  <link
    name="link_2">
    <inertial>
      <origin
        xyz="3.5562E-17 0.16752 6.9389E-18"
        rpy="0 0 0" />
      <mass
        value="5.5867" />
      <inertia
        ixx="0.12632"
        ixy="-1.9293E-17"
        ixz="3.4805E-19"
        iyy="0.011401"
        iyz="-2.3426E-18"
        izz="0.12911" />
    </inertial>
    <visual>
      <origin
        xyz="0 0 0"
        rpy="0 0 0" />
      <geometry>
        <mesh
          filename="package://robotic_arm_urdf/meshes/link_2.STL" />
      </geometry>
      <material
        name="">
        <color
          rgba="0.79216 0.81961 0.93333 1" />
      </material>
    </visual>
    <collision>
      <origin
        xyz="0 0 0"
        rpy="0 0 0" />
      <geometry>
        <mesh
          filename="package://robotic_arm_urdf/meshes/link_2.STL" />
      </geometry>
    </collision>
  </link>
  <joint
    name="joint_2"
    type="revolute">
    <origin
      xyz="0 0 0.205"
      rpy="1.5707963267949 0 -1.5707963267949" />
    <parent
      link="link_1" />
    <child
      link="link_2" />
    <axis
      xyz="0 0 -1" />
    <limit
      lower="-1.57"
      upper="1.57"
      effort="200"
      velocity="3" />
  </joint>
  <link
    name="link_3">
    <inertial>
      <origin
        xyz="-0.17893 -2.2204E-16 8.3267E-17"
        rpy="0 0 0" />
      <mass
        value="2.8262" />
      <inertia
        ixx="0.0074041"
        ixy="2.8087E-18"
        ixz="9.3947E-18"
        iyy="0.028552"
        iyz="-3.4736E-10"
        izz="0.025128" />
    </inertial>
    <visual>
      <origin
        xyz="0 0 0"
        rpy="0 0 0" />
      <geometry>
        <mesh
          filename="package://robotic_arm_urdf/meshes/link_3.STL" />
      </geometry>
      <material
        name="">
        <color
          rgba="0.79216 0.81961 0.93333 1" />
      </material>
    </visual>
    <collision>
      <origin
        xyz="0 0 0"
        rpy="0 0 0" />
      <geometry>
        <mesh
          filename="package://robotic_arm_urdf/meshes/link_3.STL" />
      </geometry>
    </collision>
  </link>
  <joint
    name="joint_3"
    type="revolute">
    <origin
      xyz="0 0.4 0"
      rpy="0 0 0" />
    <parent
      link="link_2" />
    <child
      link="link_3" />
    <axis
      xyz="0 0 1" />
    <limit
      lower="-1.57"
      upper="1.57"
      effort="300"
      velocity="3" />
  </joint>
  <link
    name="link_4">
    <inertial>
      <origin
        xyz="1.1102E-16 -0.051672 -3.4694E-17"
        rpy="0 0 0" />
      <mass
        value="1.8097" />
      <inertia
        ixx="0.0096102"
        ixy="1.3989E-18"
        ixz="6.0205E-20"
        iyy="0.0023112"
        iyz="-1.4617E-18"
        izz="0.0093908" />
    </inertial>
    <visual>
      <origin
        xyz="0 0 0"
        rpy="0 0 0" />
      <geometry>
        <mesh
          filename="package://robotic_arm_urdf/meshes/link_4.STL" />
      </geometry>
      <material
        name="">
        <color
          rgba="0.79216 0.81961 0.93333 1" />
      </material>
    </visual>
    <collision>
      <origin
        xyz="0 0 0"
        rpy="0 0 0" />
      <geometry>
        <mesh
          filename="package://robotic_arm_urdf/meshes/link_4.STL" />
      </geometry>
    </collision>
  </link>
  <joint
    name="joint_4"
    type="revolute">
    <origin
      xyz="-0.35 0 0"
      rpy="0 0 0" />
    <parent
      link="link_3" />
    <child
      link="link_4" />
    <axis
      xyz="0 0 1" />
    <limit
      lower="-1.57"
      upper="1.57"
      effort="200"
      velocity="3" />
  </joint>
  <link
    name="link_5">
    <inertial>
      <origin
        xyz="-4.8572E-17 -0.0050356 -0.002538"
        rpy="0 0 0" />
      <mass
        value="0.19053" />
      <inertia
        ixx="0.00011843"
        ixy="-1.9664E-11"
        ixz="2.4305E-20"
        iyy="0.00022817"
        iyz="1.6187E-20"
        izz="0.00030197" />
    </inertial>
    <visual>
      <origin
        xyz="0 0 0"
        rpy="0 0 0" />
      <geometry>
        <mesh
          filename="package://robotic_arm_urdf/meshes/link_5.STL" />
      </geometry>
      <material
        name="">
        <color
          rgba="0.79216 0.81961 0.93333 1" />
      </material>
    </visual>
    <collision>
      <origin
        xyz="0 0 0"
        rpy="0 0 0" />
      <geometry>
        <mesh
          filename="package://robotic_arm_urdf/meshes/link_5.STL" />
      </geometry>
    </collision>
  </link>
  <joint
    name="joint_5"
    type="revolute">
    <origin
      xyz="-0.0050356 -0.20908 0"
      rpy="1.5708 -1.5708 0" />
    <parent
      link="link_4" />
    <child
      link="link_5" />
    <axis
      xyz="0 0 1" />
    <limit
      lower="-1.57"
      upper="1.57"
      effort="150"
      velocity="2" />
  </joint>
  <link
    name="end_effector_1">
    <inertial>
      <origin
        xyz="0.016013 -1.6653E-16 0.020369"
        rpy="0 0 0" />
      <mass
        value="0.11653" />
      <inertia
        ixx="8.4875E-05"
        ixy="9.4075E-20"
        ixz="1.0258E-05"
        iyy="7.1189E-05"
        iyz="-8.0306E-21"
        izz="3.9246E-05" />
    </inertial>
    <visual>
      <origin
        xyz="0 0 0"
        rpy="0 0 0" />
      <geometry>
        <mesh
          filename="package://robotic_arm_urdf/meshes/end_effector_1.STL" />
      </geometry>
      <material
        name="">
        <color
          rgba="0.79216 0.81961 0.93333 1" />
      </material>
    </visual>
    <collision>
      <origin
        xyz="0 0 0"
        rpy="0 0 0" />
      <geometry>
        <mesh
          filename="package://robotic_arm_urdf/meshes/end_effector_1.STL" />
      </geometry>
    </collision>
  </link>
  <joint
    name="ee_joint_1"
    type="prismatic">
    <origin
      xyz="0 -0.0050356 0.020918"
      rpy="0 0 -3.1416" />
    <parent
      link="link_5" />
    <child
      link="end_effector_1" />
    <axis
      xyz="1 0 0" />
    <limit
      lower="0"
      upper="0.03"
      effort="100"
      velocity="2" />
  </joint>
  <link
    name="end_effector_2">
    <inertial>
      <origin
        xyz="-0.016013 -2.2204E-16 0.020369"
        rpy="0 0 0" />
      <mass
        value="0.11653" />
      <inertia
        ixx="8.4875E-05"
        ixy="-6.476E-20"
        ixz="-1.0258E-05"
        iyy="7.1189E-05"
        iyz="9.8527E-20"
        izz="3.9246E-05" />
    </inertial>
    <visual>
      <origin
        xyz="0 0 0"
        rpy="0 0 0" />
      <geometry>
        <mesh
          filename="package://robotic_arm_urdf/meshes/end_effector_2.STL" />
      </geometry>
      <material
        name="">
        <color
          rgba="0.79216 0.81961 0.93333 1" />
      </material>
    </visual>
    <collision>
      <origin
        xyz="0 0 0"
        rpy="0 0 0" />
      <geometry>
        <mesh
          filename="package://robotic_arm_urdf/meshes/end_effector_2.STL" />
      </geometry>
    </collision>
  </link>
  <joint
    name="ee_joint_2"
    type="prismatic">
    <origin
      xyz="0 -0.0050356 0.020918"
      rpy="0 0 -3.1416" />
    <parent
      link="link_5" />
    <child
      link="end_effector_2" />
    <axis
      xyz="1 0 0" />
    <limit
      lower="-0.03"
      upper="0"
      effort="100"
      velocity="2" />
  </joint>
</robot>